Workbook

Sheet ACARA
A52: SUSUNAN ACARA KEJURWIL ATLETIK PEKALONGAN
A53: MINGGU, 27 SEPTEMBER 2026
A55: JAM | C55: NOMOR LOMBA | E55: JENIS KELAMIN | F55: BABAK | G55: SESI
A56: PEMANGGILAN
A57: 05.30 | C57: 5000 M U 16 - 18 | E57: PUTRI | F57: FINAL | G57: PAGI 05.30
A58: 05.45 | C58: 5000 M U 16 - 18 | E58: PUTRA | F58: FINAL
A59: 06.30 | C59: 1000 m U 12 - 13 | E59: PUTRI | F59: FINAL
A60: 06.45 | C60: 1000 m U 12 - 13 | E60: PUTRA | F60: FINAL
A61: Event | B61: 5 | C61: TOLAK PELURU U 14 - 15 | E61: PUTRI | F61: FINAL
A62: Event | B62: 6 | C62: LOMPAT JAUH U 16 - 18 | E62: PUTRI | F62: FINAL
A63: Event | B63: 7 | C63: JuarAKU 30 m U 5 | E63: PUTRI | F63: FINAL
A64: Event | B64: 8 | C64: 60 m U 10 - 11 | E64: PUTRI | F64: PENYISIHAN
A65: Event | B65: 9 | C65: JuarAKU 30 m U 6 | E65: PUTRI | F65: FINAL
A66: Event | B66: 10 | C66: TOLAK PELURU U 14 - 15 | E66: PUTRA | F66: FINAL
A67: Event | B67: 11 | C67: LOMPAT JAUH U 16 - 18 | E67: PUTRA | F67: FINAL
A68: Event | B68: 12 | C68: JuarAKU 30 m U 5 | E68: PUTRA | F68: FINAL
A69: Event | B69: 13 | C69: 60 m U 10 - 11 | E69: PUTRA | F69: PENYISIHAN
A70: Event | B70: 14 | C70: JuarAKU 30 m U 6 | E70: PUTRA | F70: FINAL
A71: Event | B71: 15 | C71: TOLAK PELURU U 16 - 18 | E71: PUTRI | F71: FINAL
A72: Event | B72: 16 | C72: LOMPAT JAUH U 14 - 15 | E72: PUTRI | F72: FINAL
... A82: Event | B82: 26 | C82: 100 m U 16 - 18 | E82: PUTRA | F82: PENYISIHAN
A83: Event | B83: 27 | C83: 800 m U 16 - 18 | E83: PUTRI | F83: FINAL | G83: SORE 13.30
A84: Event | B84: 28 | C84: 800 m U 16 - 18 | E84: PUTRA | F84: FINAL
A85: Event | B85: 29 | C85: Lempar cakram U 16 - 18 | E85: PUTRI | F85: FINAL
A86: Event | B86: 30 | C86: Lempar lembing U 16 - 18 | E86: PUTRI | F86: FINAL
A87: Event | B87: 31 | C87: 400 m U16-18 | E87: PUTRI | F87: FINAL
A88: Event | B88: 32 | C88: 400 m U16-18 | E88: PUTRA | F88: FINAL
A89: Event | B89: 33 | C89: 400 m U14-15 | E89: PUTRI | F89: FINAL
A90: Event | B90: 34 | C90: 400 m U14-15 | E90: PUTRA | F90: FINAL
A91: Event | B91: 35 | C91: Lempar cakram U 16 - 18 | E91: PUTRA | F91: FINAL
A92: Event | B92: 36 | C92: Lempar lembing U 16 - 18 | E92: PUTRA | F92: FINAL
A93: Event | B93: 37 | C93: 200 m U 16 - 18 | E93: PUTRI | F93: FINAL
A94: Event | B94: 38 | C94: 200 m U 16 - 18 | E94: PUTRA | F94: FINAL
A95: Event | B95: 39 | C95: 60 m U 10 - 11 | E95: PUTRI | F95: FINAL
... A108: Event | B108: 52 | C108: Estafet 4 X 100 U 16 - 18 | E108: MIX | F108: FINAL
A111: Buku Acara Kejurwil Atletik Pekalongan
A112: Minggu, 27 September 2026
A114: Sesi Pagi
A115: Event | C115: : 1. 5000M U 16-18 Famale
A116: NO | B116: BIB | C116: Nama Atlet | D116: YR | E116: Team | F116: Time
...

Sheet Sheet 0
A1: No Dada | B1: Asal Sekolah | C1: Nama Atlet | D1: L/P | E1: YR
A2: '001 | B2: KB AISYIYAH PURI | C2: MUHAMMAD HANAN ARRAFIF | D2: L | E2: 22
A3: '002 | B3: KB Aisyiyah Qurrota A'yun 03 Binagria | C3: FARZANA YUKO PRANADIPA | D3: L | E3: 22
A4: '003 | B4: KB melati podosugih | C4: Kanaka Gilang Aditya | D4: L | E4: 20
A5: '004 | B5: MI ISLAMIYAH PRINGLANGU 01 | C5: AMANDA NAYSILLA SHANUM | D5: P | E5: 19
A6: '005 | B6: MI KRANJI 02 KEDUNGWUNI | C6: M. ADIB ASSALAMI | D6: L | E6: 19
A7: '006 | B7: MI Muhammadiyah karang asam kab.batang | C7: Ardiyan afnan wijaya | D7: L | E7: 20
A8: '007 | B8: MI NU Buaran | C8: M. Khafidz Maulana | D8: L | E8: 19
A9: '008 | B9: MI NU BUARAN | C9: Achmad Hadi Wijaya | D9: L | E9: 19
A10: '009 | B10: MI SALAFIYAH 1 KAUMAN | C10: AULIA SIFABELLA RAMADHANI | D10: P | E10: 20
A11: '010 | B11: MI SALAFIYAH 1 KAUMAN | C11: MUHAMMAD ARYAJATI LATIFUDDIN | D11: L | E11: 20
A12: '011 | B12: MI SALAFIYAH 1 KAUMAN | C12: ALZEA ZUNAIRA BUSRO | D12: P | E12: 19
A13: '012 | B13: MI SALAFIYAH 1 KAUMAN | C13: ARJUNA SHAQUILLE AKBAR | D13: L | E13: 19
... A790: '789 | B790: SMK NUSANTARA 1 COMAL | C790: MUHAMMAD SYAHRUL PRASETYAWAN | D790: L | E790: 11
A791: '790 | B791: SMK PGRI BATANG | C791: Ibnu Akbar | D791: L | E791: 09
A792: '791 | B792: SMK PGRI BATANG | C792: Khairul Aprilianto | D792: L | E792: 10
A793: '792 | B793: SMK WARUNGASEM | C793: DICKI VIKI PRATAMA | D793: L | E793: 10
A794: '793 | B794: SMKN 1 KEDUNGWUNI | C794: MUHAMMAD JAVIER AL FHARD | D794: L | E794: 10
A795: '794 | B795: SMKN 1 WARUNGASEM | C795: DANANG SUTAWIJAYA | D795: L | E795: 9
A796: '795 | B796: SMKN3PEKALONGAN | C796: Fathan Rakha Zahidan | D796: L | E796: 11
A797: '796 | B797: Smp 1 Negeri Kesesi | C797: Rizqi Tri Saputri | D797: P | E797: 13
A798: '797 | B798: Smp 2 Kota pekalongan | C798: Fachry Caesar Saputra | D798: L | E798: 12
A799: '798 | B799: SMP Ihsaniyah Tegal | C799: ASSYIFA NUR DIANDI | D799: P | E799: 11
A800: '799 | B800: SMP ISLAM AL BAYAN | C800: KEENAR ANGGIRA WIKHA | D800: P | E800: 12
A801: '800 | B801: SMP ISLAM AL BAYAN | C801: ZAHRA NAYYA AMELYA | D801: P | E801: 13
A802: '801 | B802: Smp Islam Fq Wonokerto | C802: Kevin Kian Alvaro | D802: L | E802: 12
A803: '802 | B803: SMP ISLAM FQ WONOKERTO | C803: M. SHOLLAHUDIN HIZBULLAH | D803: L | E803: 13
... A976: '975 | B976: Team Megono B | C976: Maratuzzafa | D976: P | E976: 14
A977: '976 | B977: Team SMA N 1 BOJONG | C977: Bimo Mifta Wijaya Nurali | D977: L | E977: 09
A978: '977 | B978: Team SMA N 1 BOJONG | C978: Luluk Prayogi | D978: L | E978: 08
A979: '978 | B979: Team SMA N 1 BOJONG | C979: Dita Rahma Sari | D979: P | E979: 08
A980: '979 | B980: Team SMA N 1 BOJONG | C980: Dinda Agustina | D980: P | E980: 10
A981: '980 | B981: Team SMP N 1 Kesesi | C981: Alqifari idul akbar | D981: L | E981: 09
A982: '981 | B982: Team SMP N 1 Kesesi | C982: Reihan Septriawijaya | D982: L | E982: 12
A983: '982 | B983: Team SMP N 1 Kesesi | C983: Fitri ardila mika | D983: P | E983: 11
A984: '983 | B984: Team SMP N 1 Kesesi | C984: Khaila Oktafiani | D984: P | E984: 11
A985: '984 | B985: Team MAN 02 Kota Pekalongan | C985: Mahendra Rachwa Suryandaru | D985: L | E985: 09
A986: '985 | B986: Team MAN 02 Kota Pekalongan | C986: Nur Rohman | D986: L | E986: 11
A987: '986 | B987: Team MAN 02 Kota Pekalongan | C987: Ilma Rizka Alfina | D987: P | E987: 11
A988: '987 | B988: Team MAN 02 Kota Pekalongan | C988: Anita Rosika | D988: P | E988: 10
...

Sheet Sheet1
